[2024-03-06T18:06:24.160+0000] {task_context_logger.py:104} WARNING - Marking task instance <TaskInstance: webscrapper.fetch_html_page scheduled__2024-03-02T00:05:00+00:00 [queued]> stuck in queued as failed. If the task instance has available retries, it will be retried.
[2024-03-06T18:06:25.002+0000] {task_context_logger.py:104} ERROR - Executor reports task instance <TaskInstance: webscrapper.fetch_html_page scheduled__2024-03-02T00:05:00+00:00 [queued]> finished (failed) although the task says it's queued. (Info: None) Was the task killed externally?
