[2024-03-06T18:06:24.152+0000] {task_context_logger.py:104} WARNING - Marking task instance <TaskInstance: webscrapper.fetch_html_page manual__2024-03-06T07:41:04.829573+00:00 [queued]> stuck in queued as failed. If the task instance has available retries, it will be retried.
[2024-03-06T18:06:25.067+0000] {task_context_logger.py:104} ERROR - Executor reports task instance <TaskInstance: webscrapper.fetch_html_page manual__2024-03-06T07:41:04.829573+00:00 [queued]> finished (failed) although the task says it's queued. (Info: None) Was the task killed externally?
