[2024-03-06T07:46:52.330+0000] {task_context_logger.py:104} WARNING - Marking task instance <TaskInstance: DataFetch_Pipeline.fetch_html_page scheduled__2024-03-05T00:00:00+00:00 [queued]> stuck in queued as failed. If the task instance has available retries, it will be retried.
[2024-03-06T07:46:53.489+0000] {task_context_logger.py:104} ERROR - Executor reports task instance <TaskInstance: DataFetch_Pipeline.fetch_html_page scheduled__2024-03-05T00:00:00+00:00 [queued]> finished (failed) although the task says it's queued. (Info: None) Was the task killed externally?
