[2024-03-06T19:10:57.036+0000] {taskinstance.py:1979} INFO - Dependencies all met for dep_context=non-requeueable deps ti=<TaskInstance: webscrapper.base_scrapper manual__2024-03-06T19:10:55.853873+00:00 [queued]>
[2024-03-06T19:10:57.043+0000] {taskinstance.py:1979} INFO - Dependencies all met for dep_context=requeueable deps ti=<TaskInstance: webscrapper.base_scrapper manual__2024-03-06T19:10:55.853873+00:00 [queued]>
[2024-03-06T19:10:57.044+0000] {taskinstance.py:2193} INFO - Starting attempt 1 of 1
[2024-03-06T19:10:57.054+0000] {taskinstance.py:2214} INFO - Executing <Task(PythonOperator): base_scrapper> on 2024-03-06 19:10:55.853873+00:00
[2024-03-06T19:10:57.058+0000] {standard_task_runner.py:60} INFO - Started process 468 to run task
[2024-03-06T19:10:57.061+0000] {standard_task_runner.py:87} INFO - Running: ['***', 'tasks', 'run', 'webscrapper', 'base_scrapper', 'manual__2024-03-06T19:10:55.853873+00:00', '--job-id', '83', '--raw', '--subdir', 'DAGS_FOLDER/webscrapper.py', '--cfg-path', '/tmp/tmptwpcjsrt']
[2024-03-06T19:10:57.064+0000] {standard_task_runner.py:88} INFO - Job 83: Subtask base_scrapper
[2024-03-06T19:10:57.102+0000] {task_command.py:423} INFO - Running <TaskInstance: webscrapper.base_scrapper manual__2024-03-06T19:10:55.853873+00:00 [running]> on host 21a6556b911c
[2024-03-06T19:10:57.161+0000] {taskinstance.py:2510} INFO - Exporting env vars: AIRFLOW_CTX_DAG_OWNER='***' AIRFLOW_CTX_DAG_ID='webscrapper' AIRFLOW_CTX_TASK_ID='base_scrapper' AIRFLOW_CTX_EXECUTION_DATE='2024-03-06T19:10:55.853873+00:00' AIRFLOW_CTX_TRY_NUMBER='1' AIRFLOW_CTX_DAG_RUN_ID='manual__2024-03-06T19:10:55.853873+00:00'
[2024-03-06T19:11:01.067+0000] {taskinstance.py:2728} ERROR - Task failed with exception
Traceback (most recent call last):
  File "/home/airflow/.local/lib/python3.8/site-packages/airflow/models/taskinstance.py", line 444, in _execute_task
    result = _execute_callable(context=context, **execute_callable_kwargs)
  File "/home/airflow/.local/lib/python3.8/site-packages/airflow/models/taskinstance.py", line 414, in _execute_callable
    return execute_callable(context=context, **execute_callable_kwargs)
  File "/home/airflow/.local/lib/python3.8/site-packages/airflow/operators/python.py", line 200, in execute
    return_value = self.execute_callable()
  File "/home/airflow/.local/lib/python3.8/site-packages/airflow/operators/python.py", line 217, in execute_callable
    return self.python_callable(*self.op_args, **self.op_kwargs)
  File "/opt/airflow/dags/webscrapper.py", line 32, in base_scrapper
    urllib.request.urlretrieve(finalurl, file_path)
  File "/usr/local/lib/python3.8/urllib/request.py", line 257, in urlretrieve
    tfp = open(filename, 'wb')
FileNotFoundError: [Errno 2] No such file or directory: 'tmp/data/1901_0.csv'
[2024-03-06T19:11:01.089+0000] {taskinstance.py:1149} INFO - Marking task as FAILED. dag_id=webscrapper, task_id=base_scrapper, execution_date=20240306T191055, start_date=20240306T191057, end_date=20240306T191101
[2024-03-06T19:11:01.101+0000] {standard_task_runner.py:107} ERROR - Failed to execute job 83 for task base_scrapper ([Errno 2] No such file or directory: 'tmp/data/1901_0.csv'; 468)
[2024-03-06T19:11:01.135+0000] {local_task_job_runner.py:234} INFO - Task exited with return code 1
[2024-03-06T19:11:01.151+0000] {taskinstance.py:3309} INFO - 0 downstream tasks scheduled from follow-on schedule check
